Workbook

Sheet data
A1: SubmissionDate | B1: starttime | C1: endtime | D1: caseid | E1: duration | F1: users | G1: fo_id | H1: fo_name | I1: fc_id | J1: fc_name | K1: formdef_id | L1: KEY | M1: icm_treat_status | N1: now_complete | O1: pub_to_users | P1: attempt_status | Q1: brgy_prefix
A2: 2025-08-25T03:44:14.435Z | B2: 2025-08-25T09:46:02.505+08 | C2: 2025-08-25T11:39:10.499+08 | D2: H030243024 | E2: 6446 | F2: team_e,team_f | G2: 859767 | H2: Ramie De Pedro Jr. | K2: ICM_follow_up_launch | L2: uuid:88f63169-04a1-425d-80ee-7a74fb545cd6 | N2: 1 | O2: team_e,team_f | P2: For Revisit | Q2: =LEFT(D2,7) -> H030243
A3: 2025-08-25T11:16:05.243Z | B3: 2025-08-25T12:12:28.706+08 | C3: 2025-08-25T13:49:18.388+08 | D3: H030243026 | E3: 5810 | F3: team_e,team_f | G3: 859767 | H3: Ramie De Pedro Jr. | K3: ICM_follow_up_launch | L3: uuid:6eda92a2-acc8-464d-ad1a-003ddbea27a7 | N3: 1 | O3: team_e,team_f | P3: For Revisit | Q3: =LEFT(D3,7) -> H030243
A4: 2025-08-25T11:27:47.527Z | B4: 2025-08-25T09:43:06.445+08 | C4: 2025-08-25T10:57:26.302+08 | D4: H030243033 | E4: 4430 | F4: team_e,team_f | G4: 555127 | H4: Mary May | K4: ICM_follow_up_launch | L4: uuid:9104839d-1504-4bee-9a8e-5d3470dc3515 | N4: 1 | O4: team_e,team_f | P4: For Revisit | Q4: =LEFT(D4,7) -> H030243
A5: 2025-08-25T11:27:48.291Z | B5: 2025-08-25T11:09:34.894+08 | C5: 2025-08-25T11:33:15.835+08 | D5: H030243028 | E5: 733 | F5: team_e,team_f | G5: 555127 | H5: Mary May | K5: ICM_follow_up_launch | L5: uuid:cad5d068-2f50-4629-96a9-aa9a10049d65 | N5: 0 | O5: team_e,team_f | P5: For Revisit | Q5: =LEFT(D5,7) -> H030243
A6: 2025-08-25T11:27:49.103Z | B6: 2025-08-25T13:50:40.454+08 | C6: 2025-08-25T14:46:00.327+08 | D6: H030243032 | E6: 3280 | F6: team_e,team_f | G6: 555127 | H6: Mary May | K6: ICM_follow_up_launch | L6: uuid:e34a946b-6ae2-4410-9b00-4be58fb58646 | N6: 1 | O6: team_e,team_f | P6: For Revisit | Q6: =LEFT(D6,7) -> H030243
A7: 2025-08-25T11:27:50.003Z | B7: 2025-08-25T11:33:40.051+08 | C7: 2025-08-25T13:02:44.072+08 | D7: H030243030 | E7: 5291 | F7: team_e,team_f | G7: 555127 | H7: Mary May | K7: ICM_follow_up_launch | L7: uuid:57ee7864-5af7-4b27-a9c5-74a0f3688503 | N7: 1 | O7: team_e,team_f | P7: For Revisit | Q7: =LEFT(D7,7) -> H030243
A8: 2025-08-25T11:30:54.620Z | B8: 2025-08-25T10:43:25.996+08 | C8: 2025-08-25T12:24:30.899+08 | D8: H030069008 | E8: 5384 | F8: team_c,team_d | G8: O3925718 | H8: Adrian Montecastro Ferrer | K8: ICM_follow_up_launch | L8: uuid:f38247e9-7643-463b-abda-ebf64498aba3 | N8: 1 | O8: team_c,team_d | P8: For Revisit | Q8: =LEFT(D8,7) -> H030069
A9: 2025-08-25T11:30:55.574Z | B9: 2025-08-25T12:33:59.870+08 | C9: 2025-08-25T13:34:43.797+08 | D9: H030069018 | E9: 3644 | F9: team_c,team_d | G9: O3925718 | H9: Adrian Montecastro Ferrer | K9: ICM_follow_up_launch | L9: uuid:d71e35ba-7321-401b-bcfc-fe5d558766bf | N9: 1 | O9: team_c,team_d | P9: For Revisit | Q9: =LEFT(D9,7) -> H030069
A10: 2025-08-25T11:39:28.749Z | B10: 2025-08-25T09:47:39.044+08 | C10: 2025-08-25T10:52:26.911+08 | D10: H030243034 | E10: 3888 | F10: team_e,team_f | G10: 455939 | H10: Mary Jean Villaflor | K10: ICM_follow_up_launch | L10: uuid:1cfd2ba2-ac29-4e6e-9432-6ca448daf667 | N10: 1 | O10: team_e,team_f | P10: For Revisit | Q10: =LEFT(D10,7) -> H030243
A11: 2025-08-25T11:39:29.904Z | B11: 2025-08-25T10:58:11.681+08 | C11: 2025-08-25T11:55:05.909+08 | D11: H030243035 | E11: 3414 | F11: team_e,team_f | G11: 455939 | H11: Mary Jean Villaflor | K11: ICM_follow_up_launch | L11: uuid:073a64cd-3d88-43d2-b770-d738288430ea | N11: 1 | O11: team_e,team_f | P11: For Revisit | Q11: =LEFT(D11,7) -> H030243
A12: 2025-08-25T11:41:09.601Z | B12: 2025-08-25T09:40:38.307+08 | C12: 2025-08-25T10:28:40.598+08 | D12: H030243021 | E12: 2884 | F12: team_e,team_f | G12: 729375 | H12: Janet Serafica | K12: ICM_follow_up_launch | L12: uuid:b9fba4ae-3912-4ef3-a4e5-f0d97d0a0878 | N12: 1 | O12: team_e,team_f | P12: For Revisit | Q12: =LEFT(D12,7) -> H030243
A13: 2025-08-25T11:41:10.797Z | B13: 2025-08-25T14:24:57.836+08 | C13: 2025-08-25T15:11:27.387+08 | D13: H030243029 | E13: 2750 | F13: team_e,team_f | G13: 729375 | H13: Janet Serafica | K13: ICM_follow_up_launch | L13: uuid:2020a6c9-7f95-428d-9725-c8f1d80836df | N13: 1 | O13: team_e,team_f | P13: For Revisit | Q13: =LEFT(D13,7) -> H030243
A14: 2025-08-25T11:41:10.516Z | B14: 2025-08-25T10:47:36.335+08 | C14: 2025-08-25T11:58:44.588+08 | D14: H030243019 | E14: 4211 | F14: team_e,team_f | G14: 729375 | H14: Janet Serafica | K14: ICM_follow_up_launch | L14: uuid:a75e8214-2e44-45bc-9cdc-dd495acd8186 | N14: 1 | O14: team_e,team_f | P14: For Revisit | Q14: =LEFT(D14,7) -> H030243
A15: 2025-08-25T11:45:56.065Z | B15: 2025-08-25T12:40:52.852+08 | C15: 2025-08-25T14:07:17.595+08 | D15: H030243023 | E15: 5118 | F15: team_e,team_f | G15: 841329 | H15: Aila Eli | K15: ICM_follow_up_launch | L15: uuid:24422a76-d8a3-4b2b-ab3c-86901dd0bb0d | N15: 1 | O15: team_e,team_f | P15: For Revisit | Q15: =LEFT(D15,7) -> H030243
A16: 2025-08-25T11:46:07.603Z | B16: 2025-08-25T09:47:34.923+08 | C16: 2025-08-25T12:35:25.780+08 | D16: H030243022 | E16: 10035 | F16: team_e,team_f | G16: 841329 | H16: Aila Eli | K16: ICM_follow_up_launch | L16: uuid:f96ead38-16c8-403a-811e-b5d65b115103 | N16: 1 | O16: team_e,team_f | P16: For Revisit | Q16: =LEFT(D16,7) -> H030243
A17: 2025-08-25T12:36:06.336Z | B17: 2025-08-25T10:50:13.980+08 | C17: 2025-08-25T11:53:45.055+08 | D17: H030069016 | E17: 3811 | F17: team_c,team_d | G17: M6491032 | H17: Rosevil Tayo Desamparado | K17: ICM_follow_up_launch | L17: uuid:266d51e5-4b45-447a-a197-3569494ac592 | N17: 1 | O17: team_c,team_d | P17: For Revisit | Q17: =LEFT(D17,7) -> H030069
A18: 2025-08-25T12:36:07.029Z | B18: 2025-08-25T12:09:13.476+08 | C18: 2025-08-25T13:22:13.466+08 | D18: H030069025 | E18: 4380 | F18: team_c,team_d | G18: M6491032 | H18: Rosevil Tayo Desamparado | K18: ICM_follow_up_launch | L18: uuid:3b694f49-86e2-4ed0-80b7-c466061f9b07 | N18: 1 | O18: team_c,team_d | P18: For Revisit | Q18: =LEFT(D18,7) -> H030069
A19: 2025-08-25T12:39:08.165Z | B19: 2025-08-25T14:14:26.498+08 | C19: 2025-08-25T15:13:24.111+08 | D19: H030069024 | E19: 1847 | F19: team_c,team_d | G19: K8623174 | H19: Marielle Kaye Ignacio Alonzo | K19: ICM_follow_up_launch | L19: uuid:145b1003-8109-4574-970a-95ed2d909eb3 | N19: 1 | O19: team_c,team_d | P19: For Revisit | Q19: =LEFT(D19,7) -> H030069
A20: 2025-08-25T12:39:09.088Z | B20: 2025-08-25T11:45:53.359+08 | C20: 2025-08-25T13:49:18.526+08 | D20: H030069032 | E20: 7405 | F20: team_c,team_d | G20: K8623174 | H20: Marielle Kaye Ignacio Alonzo | K20: ICM_follow_up_launch | L20: uuid:42b97ad0-ba6e-4b57-86c9-c7909ae8cd23 | N20: 1 | O20: team_c,team_d | P20: For Revisit | Q20: =LEFT(D20,7) -> H030069
A21: 2025-08-25T12:43:33.517Z | B21: 2025-08-25T10:42:58.727+08 | C21: 2025-08-25T11:59:55.913+08 | D21: H030769020 | E21: 4582 | F21: team_a,team_b | G21: C7502931 | H21: Jenny Lou Toles Estacio | K21: ICM_follow_up_launch | L21: uuid:116eff23-1ca3-4da8-9ce5-ffac5565d9c8 | N21: 1 | O21: team_a,team_b | P21: For Revisit | Q21: =LEFT(D21,7) -> H030769
A22: 2025-08-25T12:43:34.363Z | B22: 2025-08-25T12:20:50.186+08 | C22: 2025-08-25T20:43:20.307+08 | D22: H030769019 | E22: 4229 | F22: team_a,team_b | G22: C7502931 | H22: Jenny Lou Toles Estacio | K22: ICM_follow_up_launch | L22: uuid:4ae2d469-0e48-4ec1-94d4-35ee3740c331 | N22: 1 | O22: team_a,team_b | P22: For Revisit | Q22: =LEFT(D22,7) -> H030769
A23: 2025-08-25T12:48:30.448Z | B23: 2025-08-25T12:00:40.347+08 | C23: 2025-08-25T13:44:32.423+08 | D23: H030069030 | E23: 5372 | F23: team_c,team_d | G23: 365637 | H23: Trixie Marie | K23: ICM_follow_up_launch | L23: uuid:1bd1ec62-c4ff-415e-b7cf-75fc68e2b664 | N23: 1 | O23: team_c,team_d | P23: For Revisit | Q23: =LEFT(D23,7) -> H030069
A24: 2025-08-25T12:48:31.574Z | B24: 2025-08-25T11:27:37.648+08 | C24: 2025-08-25T14:28:16.808+08 | D24: H030069029 | E24: 2438 | F24: team_c,team_d | G24: 365637 | H24: Trixie Marie | K24: ICM_follow_up_launch | L24: uuid:7e723010-4697-4124-a588-ef9363a32f78 | N24: 1 | O24: team_c,team_d | P24: For Revisit | Q24: =LEFT(D24,7) -> H030069
A25: 2025-08-25T12:56:52.939Z | B25: 2025-08-25T11:15:39.664+08 | C25: 2025-08-25T12:28:42.558+08 | D25: H030769032 | E25: 4020 | F25: team_a,team_b | G25: H2846135 | H25: Annalou Empanado Encontro | K25: ICM_follow_up_launch | L25: uuid:85240357-29ef-4b76-8a8d-40ffe41c35f3 | N25: 1 | O25: team_a,team_b | P25: For Revisit | Q25: =LEFT(D25,7) -> H030769
A26: 2025-08-25T12:56:54.394Z | B26: 2025-08-25T13:02:15.085+08 | C26: 2025-08-25T14:42:27.567+08 | D26: H030769025 | E26: 5495 | F26: team_a,team_b | G26: H2846135 | H26: Annalou Empanado Encontro | K26: ICM_follow_up_launch | L26: uuid:8126eeb9-d7d4-44c3-85ab-1b265f9291f9 | N26: 1 | O26: team_a,team_b | P26: For Revisit | Q26: =LEFT(D26,7) -> H030769
A27: 2025-08-25T12:59:42.771Z | B27: 2025-08-25T11:04:38.772+08 | C27: 2025-08-25T12:35:54.803+08 | D27: H030769033 | E27: 5476 | F27: team_a,team_b | G27: D1284067 | H27: Mariel Del Rio | K27: ICM_follow_up_launch | L27: uuid:8a2837dc-c05e-4e4c-a4bc-1f427e577834 | N27: 1 | O27: team_a,team_b | P27: For Revisit | Q27: =LEFT(D27,7) -> H030769
A28: 2025-08-25T12:59:43.474Z | B28: 2025-08-25T12:54:32.784+08 | C28: 2025-08-25T13:57:22.634+08 | D28: H030769026 | E28: 3787 | F28: team_a,team_b | G28: D1284067 | H28: Mariel Del Rio | K28: ICM_follow_up_launch | L28: uuid:ff342c15-95e3-49c9-b146-eff3e91b745e | N28: 1 | O28: team_a,team_b | P28: For Revisit | Q28: =LEFT(D28,7) -> H030769
A29: 2025-08-25T13:01:45.657Z | B29: 2025-08-25T10:51:56.030+08 | C29: 2025-08-25T12:07:07.490+08 | D29: H030769030 | E29: 4511 | F29: team_a,team_b | G29: F3051749 | H29: Elenita Gicos De La Pe�a | K29: ICM_follow_up_launch | L29: uuid:38b5833c-9344-4b4a-998a-337f4703ab45 | N29: 1 | O29: team_a,team_b | P29: For Revisit | Q29: =LEFT(D29,7) -> H030769
A30: 2025-08-25T13:01:46.314Z | B30: 2025-08-25T12:42:08.772+08 | C30: 2025-08-25T15:24:32.435+08 | D30: H030769027 | E30: 9744 | F30: team_a,team_b | G30: F3051749 | H30: Elenita Gicos De La Pe�a | K30: ICM_follow_up_launch | L30: uuid:80a6dda2-4464-4ccd-a7a4-271e33f84dd4 | N30: 1 | O30: team_a,team_b | P30: For Revisit | Q30: =LEFT(D30,7) -> H030769
A31: 2025-08-25T13:05:50.173Z | B31: 2025-08-25T11:35:05.171+08 | C31: 2025-08-25T13:07:38.693+08 | D31: H030069028 | E31: 4189 | F31: team_c,team_d | G31: L2057896 | H31: Franz Reoben Posadas Geneblaza | K31: ICM_follow_up_launch | L31: uuid:c2f9b047-a842-4ce4-91b6-4c950e6c2db1 | N31: 1 | O31: team_c,team_d | P31: For Revisit | Q31: =LEFT(D31,7) -> H030069
A32: 2025-08-25T13:05:50.897Z | B32: 2025-08-25T13:08:02.622+08 | C32: 2025-08-25T14:06:12.207+08 | D32: H030069034 | E32: 2943 | F32: team_c,team_d | G32: L2057896 | H32: Franz Reoben Posadas Geneblaza | K32: ICM_follow_up_launch | L32: uuid:6f1b7c3d-ed24-4e46-a3bb-d915a23e2360 | N32: 1 | O32: team_c,team_d | P32: For Revisit | Q32: =LEFT(D32,7) -> H030069
A33: 2025-08-25T13:05:51.304Z | B33: 2025-08-25T14:06:34.102+08 | C33: 2025-08-25T14:55:57.911+08 | D33: H030069027 | E33: 1578 | F33: team_c,team_d | G33: L2057896 | H33: Franz Reoben Posadas Geneblaza | K33: ICM_follow_up_launch | L33: uuid:868bf885-7f49-4282-8088-c85819cd8cf5 | N33: 1 | O33: team_c,team_d | P33: For Revisit | Q33: =LEFT(D33,7) -> H030069
A34: 2025-08-25T13:22:54.810Z | B34: 2025-08-25T11:05:44.806+08 | C34: 2025-08-25T17:22:38.953+08 | D34: H030069026 | E34: 9853 | F34: team_c,team_d | G34: N7814260 | H34: Jemma Marie Tillo | K34: ICM_follow_up_launch | L34: uuid:283e3b8f-3953-460f-a65c-af903184a208 | N34: 1 | O34: team_c,team_d | P34: For Revisit | Q34: =LEFT(D34,7) -> H030069
A35: 2025-08-25T13:22:55.304Z | B35: 2025-08-25T13:51:15.147+08 | C35: 2025-08-25T14:52:27.078+08 | D35: H030069017 | E35: 2184 | F35: team_c,team_d | G35: N7814260 | H35: Jemma Marie Tillo | K35: ICM_follow_up_launch | L35: uuid:924acf84-80db-4934-9e34-f80ce2ad0456 | N35: 1 | O35: team_c,team_d | P35: For Revisit | Q35: =LEFT(D35,7) -> H030069
A36: 2025-08-25T13:30:12.654Z | B36: 2025-08-25T10:37:26.605+08 | C36: 2025-08-25T11:46:57.060+08 | D36: H030769024 | E36: 3964 | F36: team_a,team_b | G36: B8193462 | H36: Mark Lorens Mendoza Gilongo | K36: ICM_follow_up_launch | L36: uuid:d63e36b0-f056-4066-8774-13269f78cb0a | N36: 1 | O36: team_a,team_b | P36: For Revisit | Q36: =LEFT(D36,7) -> H030769
... A39: 2025-08-25T13:34:06.558Z | B39: 2025-08-25T12:18:48.162+08 | C39: 2025-08-25T13:46:02.164+08 | D39: H030769018 | E39: 5234 | F39: team_a,team_b | G39: G5472901 | H39: Wellyn Grace Alaban Parcia | K39: ICM_follow_up_launch | L39: uuid:5365d0a5-988f-441c-926c-7836daaa3e0d | N39: 1 | O39: team_a,team_b | P39: For Revisit | Q39: =LEFT(D39,7) -> H030769
A40: 2025-08-25T13:36:15.090Z | B40: 2025-08-25T14:27:59.282+08 | C40: 2025-08-25T21:30:46.472+08 | D40: H030769028 | E40: 6675 | F40: team_a,team_b | G40: 896791 | H40: Roland A. Bandiola jr | K40: ICM_follow_up_launch | L40: uuid:51d96826-485a-4c0e-ac5f-a46f8c51151c | N40: 1 | O40: team_a,team_b | P40: For Revisit | Q40: =LEFT(D40,7) -> H030769
A41: 2025-08-25T13:36:16.341Z | B41: 2025-08-25T12:06:33.837+08 | C41: 2025-08-25T13:41:43.096+08 | D41: H030769023 | E41: 5709 | F41: team_a,team_b | G41: 896791 | H41: Roland A. Bandiola jr | K41: ICM_follow_up_launch | L41: uuid:fdde6473-5322-4344-a59a-38801126a3e0 | N41: 1 | O41: team_a,team_b | P41: For Revisit | Q41: =LEFT(D41,7) -> H030769
A42: 2025-08-25T13:36:16.953Z | B42: 2025-08-25T09:46:41.105+08 | C42: 2025-08-25T11:52:56.943+08 | D42: H030769029 | E42: 7577 | F42: team_a,team_b | G42: 896791 | H42: Roland A. Bandiola jr | K42: ICM_follow_up_launch | L42: uuid:4b76266f-9aca-4c50-ae51-58c49f305e0a | N42: 1 | O42: team_a,team_b | P42: For Revisit | Q42: =LEFT(D42,7) -> H030769
...

Sheet dataICM
A1: =IFERROR(__xludf.DUMMYFUNCTION("IMPORTRANGE(""https://docs.google.com/spreadsheets/d/1BWcUWV5RhuYjhkz2Gmwj8nSDrlzdBDqlC055FELAcO0/edit?gid=1682311788#gid=1682311788"", ""data!A:J"")"),"SubmissionDate") -> SubmissionDate | B1: =IFERROR(__xludf.DUMMYFUNCTION("""COMPUTED_VALUE"""),"starttime") -> starttime | C1: =IFERROR(__xludf.DUMMYFUNCTION("""COMPUTED_VALUE"""),"endtime") -> endtime | D1: =IFERROR(__xludf.DUMMYFUNCTION("""COMPUTED_VALUE"""),"caseid") -> caseid | E1: =IFERROR(__xludf.DUMMYFUNCTION("""COMPUTED_VALUE"""),"fo_id") -> fo_id | F1: =IFERROR(__xludf.DUMMYFUNCTION("""COMPUTED_VALUE"""),"fo_name") -> fo_name | G1: =IFERROR(__xludf.DUMMYFUNCTION("""COMPUTED_VALUE"""),"fc_id") -> fc_id | H1: =IFERROR(__xludf.DUMMYFUNCTION("""COMPUTED_VALUE"""),"fc_name") -> fc_name | I1: =IFERROR(__xludf.DUMMYFUNCTION("""COMPUTED_VALUE"""),"formdef_id") -> formdef_id | J1: =IFERROR(__xludf.DUMMYFUNCTION("""COMPUTED_VALUE"""),"KEY") -> KEY
A2: =IFERROR(__xludf.DUMMYFUNCTION("""COMPUTED_VALUE"""),"2025-08-26T09:58:56.319Z") -> 2025-08-26T09:58:56.319Z | B2: =IFERROR(__xludf.DUMMYFUNCTION("""COMPUTED_VALUE"""),"2025-08-26T10:52:24.380+08") -> 2025-08-26T10:52:24.380+08 | C2: =IFERROR(__xludf.DUMMYFUNCTION("""COMPUTED_VALUE"""),"2025-08-26T11:05:32.574+08") -> 2025-08-26T11:05:32.574+08 | D2: =IFERROR(__xludf.DUMMYFUNCTION("""COMPUTED_VALUE"""),"H019505030") -> H019505030 | E2: =IFERROR(__xludf.DUMMYFUNCTION("""COMPUTED_VALUE"""),729375.0) -> 729375 | F2: =IFERROR(__xludf.DUMMYFUNCTION("""COMPUTED_VALUE"""),"Janet Serafica") -> Janet Serafica | I2: =IFERROR(__xludf.DUMMYFUNCTION("""COMPUTED_VALUE"""),"ICM_Business_linked_launch") -> ICM_Business_linked_launch | J2: =IFERROR(__xludf.DUMMYFUNCTION("""COMPUTED_VALUE"""),"uuid:7059b204-34b6-4769-a2c3-17ad4a9f91bc") -> uuid:7059b204-34b6-4769-a2c3-17ad4a9f91bc
A3: =IFERROR(__xludf.DUMMYFUNCTION("""COMPUTED_VALUE"""),"2025-08-26T09:58:57.308Z") -> 2025-08-26T09:58:57.308Z | B3: =IFERROR(__xludf.DUMMYFUNCTION("""COMPUTED_VALUE"""),"2025-08-26T11:55:19.232+08") -> 2025-08-26T11:55:19.232+08 | C3: =IFERROR(__xludf.DUMMYFUNCTION("""COMPUTED_VALUE"""),"2025-08-26T12:05:20.601+08") -> 2025-08-26T12:05:20.601+08 | D3: =IFERROR(__xludf.DUMMYFUNCTION("""COMPUTED_VALUE"""),"H019505016") -> H019505016 | E3: =IFERROR(__xludf.DUMMYFUNCTION("""COMPUTED_VALUE"""),729375.0) -> 729375 | F3: =IFERROR(__xludf.DUMMYFUNCTION("""COMPUTED_VALUE"""),"Janet Serafica") -> Janet Serafica | I3: =IFERROR(__xludf.DUMMYFUNCTION("""COMPUTED_VALUE"""),"ICM_Business_linked_launch") -> ICM_Business_linked_launch | J3: =IFERROR(__xludf.DUMMYFUNCTION("""COMPUTED_VALUE"""),"uuid:57cf2ec6-f20d-4530-9d2f-746f98586b13") -> uuid:57cf2ec6-f20d-4530-9d2f-746f98586b13
A4: =IFERROR(__xludf.DUMMYFUNCTION("""COMPUTED_VALUE"""),"2025-08-26T09:58:58.034Z") -> 2025-08-26T09:58:58.034Z | B4: =IFERROR(__xludf.DUMMYFUNCTION("""COMPUTED_VALUE"""),"2025-08-26T16:21:40.440+08") -> 2025-08-26T16:21:40.440+08 | C4: =IFERROR(__xludf.DUMMYFUNCTION("""COMPUTED_VALUE"""),"2025-08-26T16:31:25.202+08") -> 2025-08-26T16:31:25.202+08 | D4: =IFERROR(__xludf.DUMMYFUNCTION("""COMPUTED_VALUE"""),"H019505029") -> H019505029 | E4: =IFERROR(__xludf.DUMMYFUNCTION("""COMPUTED_VALUE"""),729375.0) -> 729375 | F4: =IFERROR(__xludf.DUMMYFUNCTION("""COMPUTED_VALUE"""),"Janet Serafica") -> Janet Serafica | I4: =IFERROR(__xludf.DUMMYFUNCTION("""COMPUTED_VALUE"""),"ICM_Business_linked_launch") -> ICM_Business_linked_launch | J4: =IFERROR(__xludf.DUMMYFUNCTION("""COMPUTED_VALUE"""),"uuid:5decea22-c084-4bf9-9319-015509b24494") -> uuid:5decea22-c084-4bf9-9319-015509b24494
A5: =IFERROR(__xludf.DUMMYFUNCTION("""COMPUTED_VALUE"""),"2025-08-26T11:08:04.174Z") -> 2025-08-26T11:08:04.174Z | B5: =IFERROR(__xludf.DUMMYFUNCTION("""COMPUTED_VALUE"""),"2025-08-26T12:59:09.953+08") -> 2025-08-26T12:59:09.953+08 | C5: =IFERROR(__xludf.DUMMYFUNCTION("""COMPUTED_VALUE"""),"2025-08-26T13:11:38.183+08") -> 2025-08-26T13:11:38.183+08 | D5: =IFERROR(__xludf.DUMMYFUNCTION("""COMPUTED_VALUE"""),"H019505033") -> H019505033 | E5: =IFERROR(__xludf.DUMMYFUNCTION("""COMPUTED_VALUE"""),"S2671943") -> S2671943 | F5: =IFERROR(__xludf.DUMMYFUNCTION("""COMPUTED_VALUE"""),"Marvin Mondia") -> Marvin Mondia | I5: =IFERROR(__xludf.DUMMYFUNCTION("""COMPUTED_VALUE"""),"ICM_Business_linked_launch") -> ICM_Business_linked_launch | J5: =IFERROR(__xludf.DUMMYFUNCTION("""COMPUTED_VALUE"""),"uuid:9f9a5195-c558-440c-9327-c0068b23f1d1") -> uuid:9f9a5195-c558-440c-9327-c0068b23f1d1
A6: =IFERROR(__xludf.DUMMYFUNCTION("""COMPUTED_VALUE"""),"2025-08-26T11:08:05.164Z") -> 2025-08-26T11:08:05.164Z | B6: =IFERROR(__xludf.DUMMYFUNCTION("""COMPUTED_VALUE"""),"2025-08-26T16:54:07.888+08") -> 2025-08-26T16:54:07.888+08 | C6: =IFERROR(__xludf.DUMMYFUNCTION("""COMPUTED_VALUE"""),"2025-08-26T17:05:16.217+08") -> 2025-08-26T17:05:16.217+08 | D6: =IFERROR(__xludf.DUMMYFUNCTION("""COMPUTED_VALUE"""),"H019505025") -> H019505025 | E6: =IFERROR(__xludf.DUMMYFUNCTION("""COMPUTED_VALUE"""),"S2671943") -> S2671943 | F6: =IFERROR(__xludf.DUMMYFUNCTION("""COMPUTED_VALUE"""),"Marvin Mondia") -> Marvin Mondia | I6: =IFERROR(__xludf.DUMMYFUNCTION("""COMPUTED_VALUE"""),"ICM_Business_linked_launch") -> ICM_Business_linked_launch | J6: =IFERROR(__xludf.DUMMYFUNCTION("""COMPUTED_VALUE"""),"uuid:2990674e-e623-4d26-8415-d801b24c16ee") -> uuid:2990674e-e623-4d26-8415-d801b24c16ee
A7: =IFERROR(__xludf.DUMMYFUNCTION("""COMPUTED_VALUE"""),"2025-08-26T11:22:53.167Z") -> 2025-08-26T11:22:53.167Z | B7: =IFERROR(__xludf.DUMMYFUNCTION("""COMPUTED_VALUE"""),"2025-08-26T10:29:55.627+08") -> 2025-08-26T10:29:55.627+08 | C7: =IFERROR(__xludf.DUMMYFUNCTION("""COMPUTED_VALUE"""),"2025-08-26T10:36:51.866+08") -> 2025-08-26T10:36:51.866+08 | D7: =IFERROR(__xludf.DUMMYFUNCTION("""COMPUTED_VALUE"""),"H019575018") -> H019575018 | E7: =IFERROR(__xludf.DUMMYFUNCTION("""COMPUTED_VALUE"""),555127.0) -> 555127 | F7: =IFERROR(__xludf.DUMMYFUNCTION("""COMPUTED_VALUE"""),"Mary May") -> Mary May | I7: =IFERROR(__xludf.DUMMYFUNCTION("""COMPUTED_VALUE"""),"ICM_Business_linked_launch") -> ICM_Business_linked_launch | J7: =IFERROR(__xludf.DUMMYFUNCTION("""COMPUTED_VALUE"""),"uuid:dd243afd-6c89-4924-875f-bd0756b9765e") -> uuid:dd243afd-6c89-4924-875f-bd0756b9765e
A8: =IFERROR(__xludf.DUMMYFUNCTION("""COMPUTED_VALUE"""),"2025-08-26T11:22:54.335Z") -> 2025-08-26T11:22:54.335Z | B8: =IFERROR(__xludf.DUMMYFUNCTION("""COMPUTED_VALUE"""),"2025-08-26T13:04:07.705+08") -> 2025-08-26T13:04:07.705+08 | C8: =IFERROR(__xludf.DUMMYFUNCTION("""COMPUTED_VALUE"""),"2025-08-26T13:08:22.483+08") -> 2025-08-26T13:08:22.483+08 | D8: =IFERROR(__xludf.DUMMYFUNCTION("""COMPUTED_VALUE"""),"H019575021") -> H019575021 | E8: =IFERROR(__xludf.DUMMYFUNCTION("""COMPUTED_VALUE"""),555127.0) -> 555127 | F8: =IFERROR(__xludf.DUMMYFUNCTION("""COMPUTED_VALUE"""),"Mary May") -> Mary May | I8: =IFERROR(__xludf.DUMMYFUNCTION("""COMPUTED_VALUE"""),"ICM_Business_linked_launch") -> ICM_Business_linked_launch | J8: =IFERROR(__xludf.DUMMYFUNCTION("""COMPUTED_VALUE"""),"uuid:239a3c32-0934-4eb5-81ed-4e590c3f2149") -> uuid:239a3c32-0934-4eb5-81ed-4e590c3f2149
A9: =IFERROR(__xludf.DUMMYFUNCTION("""COMPUTED_VALUE"""),"2025-08-26T11:22:53.502Z") -> 2025-08-26T11:22:53.502Z | B9: =IFERROR(__xludf.DUMMYFUNCTION("""COMPUTED_VALUE"""),"2025-08-26T11:40:36.865+08") -> 2025-08-26T11:40:36.865+08 | C9: =IFERROR(__xludf.DUMMYFUNCTION("""COMPUTED_VALUE"""),"2025-08-26T11:44:30.838+08") -> 2025-08-26T11:44:30.838+08 | D9: =IFERROR(__xludf.DUMMYFUNCTION("""COMPUTED_VALUE"""),"H019575031") -> H019575031 | E9: =IFERROR(__xludf.DUMMYFUNCTION("""COMPUTED_VALUE"""),555127.0) -> 555127 | F9: =IFERROR(__xludf.DUMMYFUNCTION("""COMPUTED_VALUE"""),"Mary May") -> Mary May | I9: =IFERROR(__xludf.DUMMYFUNCTION("""COMPUTED_VALUE"""),"ICM_Business_linked_launch") -> ICM_Business_linked_launch | J9: =IFERROR(__xludf.DUMMYFUNCTION("""COMPUTED_VALUE"""),"uuid:66575612-96a3-49d6-867d-9a54e43cd23a") -> uuid:66575612-96a3-49d6-867d-9a54e43cd23a
A10: =IFERROR(__xludf.DUMMYFUNCTION("""COMPUTED_VALUE"""),"2025-08-26T11:22:54.972Z") -> 2025-08-26T11:22:54.972Z | B10: =IFERROR(__xludf.DUMMYFUNCTION("""COMPUTED_VALUE"""),"2025-08-26T15:25:28.565+08") -> 2025-08-26T15:25:28.565+08 | C10: =IFERROR(__xludf.DUMMYFUNCTION("""COMPUTED_VALUE"""),"2025-08-26T17:59:33.431+08") -> 2025-08-26T17:59:33.431+08 | D10: =IFERROR(__xludf.DUMMYFUNCTION("""COMPUTED_VALUE"""),"H019575027") -> H019575027 | E10: =IFERROR(__xludf.DUMMYFUNCTION("""COMPUTED_VALUE"""),555127.0) -> 555127 | F10: =IFERROR(__xludf.DUMMYFUNCTION("""COMPUTED_VALUE"""),"Mary May") -> Mary May | I10: =IFERROR(__xludf.DUMMYFUNCTION("""COMPUTED_VALUE"""),"ICM_Business_linked_launch") -> ICM_Business_linked_launch | J10: =IFERROR(__xludf.DUMMYFUNCTION("""COMPUTED_VALUE"""),"uuid:4681dcc7-7951-4b32-adf0-e9e7106c4a99") -> uuid:4681dcc7-7951-4b32-adf0-e9e7106c4a99
A11: =IFERROR(__xludf.DUMMYFUNCTION("""COMPUTED_VALUE"""),"2025-08-26T11:24:06.589Z") -> 2025-08-26T11:24:06.589Z | B11: =IFERROR(__xludf.DUMMYFUNCTION("""COMPUTED_VALUE"""),"2025-08-26T11:52:20.016+08") -> 2025-08-26T11:52:20.016+08 | C11: =IFERROR(__xludf.DUMMYFUNCTION("""COMPUTED_VALUE"""),"2025-08-26T12:11:44.487+08") -> 2025-08-26T12:11:44.487+08 | D11: =IFERROR(__xludf.DUMMYFUNCTION("""COMPUTED_VALUE"""),"H019505017") -> H019505017 | E11: =IFERROR(__xludf.DUMMYFUNCTION("""COMPUTED_VALUE"""),859767.0) -> 859767 | F11: =IFERROR(__xludf.DUMMYFUNCTION("""COMPUTED_VALUE"""),"Ramie De Pedro Jr.") -> Ramie De Pedro Jr. | I11: =IFERROR(__xludf.DUMMYFUNCTION("""COMPUTED_VALUE"""),"ICM_Business_linked_launch") -> ICM_Business_linked_launch | J11: =IFERROR(__xludf.DUMMYFUNCTION("""COMPUTED_VALUE"""),"uuid:f1517d9c-d2fd-4989-93cd-1ae6fc7172eb") -> uuid:f1517d9c-d2fd-4989-93cd-1ae6fc7172eb
A12: =IFERROR(__xludf.DUMMYFUNCTION("""COMPUTED_VALUE"""),"2025-08-26T11:24:07.776Z") -> 2025-08-26T11:24:07.776Z | B12: =IFERROR(__xludf.DUMMYFUNCTION("""COMPUTED_VALUE"""),"2025-08-26T14:34:11.802+08") -> 2025-08-26T14:34:11.802+08 | C12: =IFERROR(__xludf.DUMMYFUNCTION("""COMPUTED_VALUE"""),"2025-08-26T17:59:38.649+08") -> 2025-08-26T17:59:38.649+08 | D12: =IFERROR(__xludf.DUMMYFUNCTION("""COMPUTED_VALUE"""),"H019505018") -> H019505018 | E12: =IFERROR(__xludf.DUMMYFUNCTION("""COMPUTED_VALUE"""),859767.0) -> 859767 | F12: =IFERROR(__xludf.DUMMYFUNCTION("""COMPUTED_VALUE"""),"Ramie De Pedro Jr.") -> Ramie De Pedro Jr. | I12: =IFERROR(__xludf.DUMMYFUNCTION("""COMPUTED_VALUE"""),"ICM_Business_linked_launch") -> ICM_Business_linked_launch | J12: =IFERROR(__xludf.DUMMYFUNCTION("""COMPUTED_VALUE"""),"uuid:22532a47-a5ea-44a6-a292-7ecfd3327cf3") -> uuid:22532a47-a5ea-44a6-a292-7ecfd3327cf3
A13: =IFERROR(__xludf.DUMMYFUNCTION("""COMPUTED_VALUE"""),"2025-08-26T11:24:08.080Z") -> 2025-08-26T11:24:08.080Z | B13: =IFERROR(__xludf.DUMMYFUNCTION("""COMPUTED_VALUE"""),"2025-08-26T17:10:18.517+08") -> 2025-08-26T17:10:18.517+08 | C13: =IFERROR(__xludf.DUMMYFUNCTION("""COMPUTED_VALUE"""),"2025-08-26T17:20:09.891+08") -> 2025-08-26T17:20:09.891+08 | D13: =IFERROR(__xludf.DUMMYFUNCTION("""COMPUTED_VALUE"""),"H019505019") -> H019505019 | E13: =IFERROR(__xludf.DUMMYFUNCTION("""COMPUTED_VALUE"""),859767.0) -> 859767 | F13: =IFERROR(__xludf.DUMMYFUNCTION("""COMPUTED_VALUE"""),"Ramie De Pedro Jr.") -> Ramie De Pedro Jr. | I13: =IFERROR(__xludf.DUMMYFUNCTION("""COMPUTED_VALUE"""),"ICM_Business_linked_launch") -> ICM_Business_linked_launch | J13: =IFERROR(__xludf.DUMMYFUNCTION("""COMPUTED_VALUE"""),"uuid:2c644a95-0dde-4648-b712-266faa83dbb5") -> uuid:2c644a95-0dde-4648-b712-266faa83dbb5
A14: =IFERROR(__xludf.DUMMYFUNCTION("""COMPUTED_VALUE"""),"2025-08-26T11:26:41.842Z") -> 2025-08-26T11:26:41.842Z | B14: =IFERROR(__xludf.DUMMYFUNCTION("""COMPUTED_VALUE"""),"2025-08-26T10:09:28.711+08") -> 2025-08-26T10:09:28.711+08 | C14: =IFERROR(__xludf.DUMMYFUNCTION("""COMPUTED_VALUE"""),"2025-08-26T10:26:28.988+08") -> 2025-08-26T10:26:28.988+08 | D14: =IFERROR(__xludf.DUMMYFUNCTION("""COMPUTED_VALUE"""),"H030255019") -> H030255019 | E14: =IFERROR(__xludf.DUMMYFUNCTION("""COMPUTED_VALUE"""),"N7814260") -> N7814260 | F14: =IFERROR(__xludf.DUMMYFUNCTION("""COMPUTED_VALUE"""),"Jemma Marie Tillo") -> Jemma Marie Tillo | I14: =IFERROR(__xludf.DUMMYFUNCTION("""COMPUTED_VALUE"""),"ICM_Business_linked_launch") -> ICM_Business_linked_launch | J14: =IFERROR(__xludf.DUMMYFUNCTION("""COMPUTED_VALUE"""),"uuid:eb6a79c8-e530-4d04-a682-c75b42de494e") -> uuid:eb6a79c8-e530-4d04-a682-c75b42de494e
A15: =IFERROR(__xludf.DUMMYFUNCTION("""COMPUTED_VALUE"""),"2025-08-26T11:26:42.385Z") -> 2025-08-26T11:26:42.385Z | B15: =IFERROR(__xludf.DUMMYFUNCTION("""COMPUTED_VALUE"""),"2025-08-26T11:38:33.634+08") -> 2025-08-26T11:38:33.634+08 | C15: =IFERROR(__xludf.DUMMYFUNCTION("""COMPUTED_VALUE"""),"2025-08-26T12:08:26.330+08") -> 2025-08-26T12:08:26.330+08 | D15: =IFERROR(__xludf.DUMMYFUNCTION("""COMPUTED_VALUE"""),"H030255017") -> H030255017 | E15: =IFERROR(__xludf.DUMMYFUNCTION("""COMPUTED_VALUE"""),"N7814260") -> N7814260 | F15: =IFERROR(__xludf.DUMMYFUNCTION("""COMPUTED_VALUE"""),"Jemma Marie Tillo") -> Jemma Marie Tillo | I15: =IFERROR(__xludf.DUMMYFUNCTION("""COMPUTED_VALUE"""),"ICM_Business_linked_launch") -> ICM_Business_linked_launch | J15: =IFERROR(__xludf.DUMMYFUNCTION("""COMPUTED_VALUE"""),"uuid:f4db21e1-0307-448c-83d4-e949b217ca6c") -> uuid:f4db21e1-0307-448c-83d4-e949b217ca6c
A16: =IFERROR(__xludf.DUMMYFUNCTION("""COMPUTED_VALUE"""),"2025-08-26T11:26:42.739Z") -> 2025-08-26T11:26:42.739Z | B16: =IFERROR(__xludf.DUMMYFUNCTION("""COMPUTED_VALUE"""),"2025-08-26T13:34:44.343+08") -> 2025-08-26T13:34:44.343+08 | C16: =IFERROR(__xludf.DUMMYFUNCTION("""COMPUTED_VALUE"""),"2025-08-26T13:50:26.407+08") -> 2025-08-26T13:50:26.407+08 | D16: =IFERROR(__xludf.DUMMYFUNCTION("""COMPUTED_VALUE"""),"H030255022") -> H030255022 | E16: =IFERROR(__xludf.DUMMYFUNCTION("""COMPUTED_VALUE"""),"N7814260") -> N7814260 | F16: =IFERROR(__xludf.DUMMYFUNCTION("""COMPUTED_VALUE"""),"Jemma Marie Tillo") -> Jemma Marie Tillo | I16: =IFERROR(__xludf.DUMMYFUNCTION("""COMPUTED_VALUE"""),"ICM_Business_linked_launch") -> ICM_Business_linked_launch | J16: =IFERROR(__xludf.DUMMYFUNCTION("""COMPUTED_VALUE"""),"uuid:67446a00-7119-4f87-8d9b-c8f8ff139d99") -> uuid:67446a00-7119-4f87-8d9b-c8f8ff139d99
A17: =IFERROR(__xludf.DUMMYFUNCTION("""COMPUTED_VALUE"""),"2025-08-26T11:36:13.802Z") -> 2025-08-26T11:36:13.802Z | B17: =IFERROR(__xludf.DUMMYFUNCTION("""COMPUTED_VALUE"""),"2025-08-26T13:28:31.339+08") -> 2025-08-26T13:28:31.339+08 | C17: =IFERROR(__xludf.DUMMYFUNCTION("""COMPUTED_VALUE"""),"2025-08-26T14:03:22.477+08") -> 2025-08-26T14:03:22.477+08 | D17: =IFERROR(__xludf.DUMMYFUNCTION("""COMPUTED_VALUE"""),"H019575019") -> H019575019 | E17: =IFERROR(__xludf.DUMMYFUNCTION("""COMPUTED_VALUE"""),841329.0) -> 841329 | F17: =IFERROR(__xludf.DUMMYFUNCTION("""COMPUTED_VALUE"""),"Aila Eli") -> Aila Eli | I17: =IFERROR(__xludf.DUMMYFUNCTION("""COMPUTED_VALUE"""),"ICM_Business_linked_launch") -> ICM_Business_linked_launch | J17: =IFERROR(__xludf.DUMMYFUNCTION("""COMPUTED_VALUE"""),"uuid:87156853-9874-418a-9e26-5fc0cca2d8ab") -> uuid:87156853-9874-418a-9e26-5fc0cca2d8ab
A18: =IFERROR(__xludf.DUMMYFUNCTION("""COMPUTED_VALUE"""),"2025-08-26T11:36:15.082Z") -> 2025-08-26T11:36:15.082Z | B18: =IFERROR(__xludf.DUMMYFUNCTION("""COMPUTED_VALUE"""),"2025-08-26T15:22:33.841+08") -> 2025-08-26T15:22:33.841+08 | C18: =IFERROR(__xludf.DUMMYFUNCTION("""COMPUTED_VALUE"""),"2025-08-26T15:28:49.232+08") -> 2025-08-26T15:28:49.232+08 | D18: =IFERROR(__xludf.DUMMYFUNCTION("""COMPUTED_VALUE"""),"H019575025") -> H019575025 | E18: =IFERROR(__xludf.DUMMYFUNCTION("""COMPUTED_VALUE"""),841329.0) -> 841329 | F18: =IFERROR(__xludf.DUMMYFUNCTION("""COMPUTED_VALUE"""),"Aila Eli") -> Aila Eli | I18: =IFERROR(__xludf.DUMMYFUNCTION("""COMPUTED_VALUE"""),"ICM_Business_linked_launch") -> ICM_Business_linked_launch | J18: =IFERROR(__xludf.DUMMYFUNCTION("""COMPUTED_VALUE"""),"uuid:bfe6f363-de10-43ba-970f-486be2be7803") -> uuid:bfe6f363-de10-43ba-970f-486be2be7803
A19: =IFERROR(__xludf.DUMMYFUNCTION("""COMPUTED_VALUE"""),"2025-08-26T11:36:14.724Z") -> 2025-08-26T11:36:14.724Z | B19: =IFERROR(__xludf.DUMMYFUNCTION("""COMPUTED_VALUE"""),"2025-08-26T10:55:42.938+08") -> 2025-08-26T10:55:42.938+08 | C19: =IFERROR(__xludf.DUMMYFUNCTION("""COMPUTED_VALUE"""),"2025-08-26T14:04:13.411+08") -> 2025-08-26T14:04:13.411+08 | D19: =IFERROR(__xludf.DUMMYFUNCTION("""COMPUTED_VALUE"""),"H019575016") -> H019575016 | E19: =IFERROR(__xludf.DUMMYFUNCTION("""COMPUTED_VALUE"""),841329.0) -> 841329 | F19: =IFERROR(__xludf.DUMMYFUNCTION("""COMPUTED_VALUE"""),"Aila Eli") -> Aila Eli | I19: =IFERROR(__xludf.DUMMYFUNCTION("""COMPUTED_VALUE"""),"ICM_Business_linked_launch") -> ICM_Business_linked_launch | J19: =IFERROR(__xludf.DUMMYFUNCTION("""COMPUTED_VALUE"""),"uuid:cda8c8a9-2172-4579-a577-370452d69df7") -> uuid:cda8c8a9-2172-4579-a577-370452d69df7
A20: =IFERROR(__xludf.DUMMYFUNCTION("""COMPUTED_VALUE"""),"2025-08-26T11:38:31.380Z") -> 2025-08-26T11:38:31.380Z | B20: =IFERROR(__xludf.DUMMYFUNCTION("""COMPUTED_VALUE"""),"2025-08-26T09:57:29.173+08") -> 2025-08-26T09:57:29.173+08 | C20: =IFERROR(__xludf.DUMMYFUNCTION("""COMPUTED_VALUE"""),"2025-08-26T10:00:38.591+08") -> 2025-08-26T10:00:38.591+08 | D20: =IFERROR(__xludf.DUMMYFUNCTION("""COMPUTED_VALUE"""),"H030375033") -> H030375033 | E20: =IFERROR(__xludf.DUMMYFUNCTION("""COMPUTED_VALUE"""),"L2057896") -> L2057896 | F20: =IFERROR(__xludf.DUMMYFUNCTION("""COMPUTED_VALUE"""),"Franz Reoben Posadas Geneblaza") -> Franz Reoben Posadas Geneblaza | I20: =IFERROR(__xludf.DUMMYFUNCTION("""COMPUTED_VALUE"""),"ICM_Business_linked_launch") -> ICM_Business_linked_launch | J20: =IFERROR(__xludf.DUMMYFUNCTION("""COMPUTED_VALUE"""),"uuid:b6d00463-c473-4027-82ad-885fbc4208ea") -> uuid:b6d00463-c473-4027-82ad-885fbc4208ea
A21: =IFERROR(__xludf.DUMMYFUNCTION("""COMPUTED_VALUE"""),"2025-08-26T11:38:32.131Z") -> 2025-08-26T11:38:32.131Z | B21: =IFERROR(__xludf.DUMMYFUNCTION("""COMPUTED_VALUE"""),"2025-08-26T11:14:23.061+08") -> 2025-08-26T11:14:23.061+08 | C21: =IFERROR(__xludf.DUMMYFUNCTION("""COMPUTED_VALUE"""),"2025-08-26T12:17:41.823+08") -> 2025-08-26T12:17:41.823+08 | D21: =IFERROR(__xludf.DUMMYFUNCTION("""COMPUTED_VALUE"""),"H030375035") -> H030375035 | E21: =IFERROR(__xludf.DUMMYFUNCTION("""COMPUTED_VALUE"""),"L2057896") -> L2057896 | F21: =IFERROR(__xludf.DUMMYFUNCTION("""COMPUTED_VALUE"""),"Franz Reoben Posadas Geneblaza") -> Franz Reoben Posadas Geneblaza | I21: =IFERROR(__xludf.DUMMYFUNCTION("""COMPUTED_VALUE"""),"ICM_Business_linked_launch") -> ICM_Business_linked_launch | J21: =IFERROR(__xludf.DUMMYFUNCTION("""COMPUTED_VALUE"""),"uuid:e5d50cdb-1fe3-4e13-b81e-2c48644ba268") -> uuid:e5d50cdb-1fe3-4e13-b81e-2c48644ba268
A22: =IFERROR(__xludf.DUMMYFUNCTION("""COMPUTED_VALUE"""),"2025-08-26T11:38:32.927Z") -> 2025-08-26T11:38:32.927Z | B22: =IFERROR(__xludf.DUMMYFUNCTION("""COMPUTED_VALUE"""),"2025-08-26T15:04:51.582+08") -> 2025-08-26T15:04:51.582+08 | C22: =IFERROR(__xludf.DUMMYFUNCTION("""COMPUTED_VALUE"""),"2025-08-26T15:09:34.552+08") -> 2025-08-26T15:09:34.552+08 | D22: =IFERROR(__xludf.DUMMYFUNCTION("""COMPUTED_VALUE"""),"H030375028") -> H030375028 | E22: =IFERROR(__xludf.DUMMYFUNCTION("""COMPUTED_VALUE"""),"L2057896") -> L2057896 | F22: =IFERROR(__xludf.DUMMYFUNCTION("""COMPUTED_VALUE"""),"Franz Reoben Posadas Geneblaza") -> Franz Reoben Posadas Geneblaza | I22: =IFERROR(__xludf.DUMMYFUNCTION("""COMPUTED_VALUE"""),"ICM_Business_linked_launch") -> ICM_Business_linked_launch | J22: =IFERROR(__xludf.DUMMYFUNCTION("""COMPUTED_VALUE"""),"uuid:d7b0b15c-55a8-4563-ae80-f7fdfb44ac72") -> uuid:d7b0b15c-55a8-4563-ae80-f7fdfb44ac72
A23: =IFERROR(__xludf.DUMMYFUNCTION("""COMPUTED_VALUE"""),"2025-08-26T11:39:06.948Z") -> 2025-08-26T11:39:06.948Z | B23: =IFERROR(__xludf.DUMMYFUNCTION("""COMPUTED_VALUE"""),"2025-08-26T09:49:09.290+08") -> 2025-08-26T09:49:09.290+08 | C23: =IFERROR(__xludf.DUMMYFUNCTION("""COMPUTED_VALUE"""),"2025-08-26T10:01:10.612+08") -> 2025-08-26T10:01:10.612+08 | D23: =IFERROR(__xludf.DUMMYFUNCTION("""COMPUTED_VALUE"""),"H030821025") -> H030821025 | E23: =IFERROR(__xludf.DUMMYFUNCTION("""COMPUTED_VALUE"""),"H2846135") -> H2846135 | F23: =IFERROR(__xludf.DUMMYFUNCTION("""COMPUTED_VALUE"""),"Annalou Empanado Encontro") -> Annalou Empanado Encontro | I23: =IFERROR(__xludf.DUMMYFUNCTION("""COMPUTED_VALUE"""),"ICM_Business_linked_launch") -> ICM_Business_linked_launch | J23: =IFERROR(__xludf.DUMMYFUNCTION("""COMPUTED_VALUE"""),"uuid:18dac40d-2062-4a13-8237-01ed5e962a1e") -> uuid:18dac40d-2062-4a13-8237-01ed5e962a1e
A24: =IFERROR(__xludf.DUMMYFUNCTION("""COMPUTED_VALUE"""),"2025-08-26T11:39:07.355Z") -> 2025-08-26T11:39:07.355Z | B24: =IFERROR(__xludf.DUMMYFUNCTION("""COMPUTED_VALUE"""),"2025-08-26T11:24:53.168+08") -> 2025-08-26T11:24:53.168+08 | C24: =IFERROR(__xludf.DUMMYFUNCTION("""COMPUTED_VALUE"""),"2025-08-26T12:01:50.712+08") -> 2025-08-26T12:01:50.712+08 | D24: =IFERROR(__xludf.DUMMYFUNCTION("""COMPUTED_VALUE"""),"H030821019") -> H030821019 | E24: =IFERROR(__xludf.DUMMYFUNCTION("""COMPUTED_VALUE"""),"H2846135") -> H2846135 | F24: =IFERROR(__xludf.DUMMYFUNCTION("""COMPUTED_VALUE"""),"Annalou Empanado Encontro") -> Annalou Empanado Encontro | I24: =IFERROR(__xludf.DUMMYFUNCTION("""COMPUTED_VALUE"""),"ICM_Business_linked_launch") -> ICM_Business_linked_launch | J24: =IFERROR(__xludf.DUMMYFUNCTION("""COMPUTED_VALUE"""),"uuid:83344ab7-ebaa-4be4-853e-b0695afe8f0e") -> uuid:83344ab7-ebaa-4be4-853e-b0695afe8f0e
A25: =IFERROR(__xludf.DUMMYFUNCTION("""COMPUTED_VALUE"""),"2025-08-26T11:39:08.212Z") -> 2025-08-26T11:39:08.212Z | B25: =IFERROR(__xludf.DUMMYFUNCTION("""COMPUTED_VALUE"""),"2025-08-26T13:26:23.950+08") -> 2025-08-26T13:26:23.950+08 | C25: =IFERROR(__xludf.DUMMYFUNCTION("""COMPUTED_VALUE"""),"2025-08-26T13:28:36.232+08") -> 2025-08-26T13:28:36.232+08 | D25: =IFERROR(__xludf.DUMMYFUNCTION("""COMPUTED_VALUE"""),"H030821016") -> H030821016 | E25: =IFERROR(__xludf.DUMMYFUNCTION("""COMPUTED_VALUE"""),"H2846135") -> H2846135 | F25: =IFERROR(__xludf.DUMMYFUNCTION("""COMPUTED_VALUE"""),"Annalou Empanado Encontro") -> Annalou Empanado Encontro | I25: =IFERROR(__xludf.DUMMYFUNCTION("""COMPUTED_VALUE"""),"ICM_Business_linked_launch") -> ICM_Business_linked_launch | J25: =IFERROR(__xludf.DUMMYFUNCTION("""COMPUTED_VALUE"""),"uuid:cfc9a302-50ed-460c-af5e-9a47082e1f1e") -> uuid:cfc9a302-50ed-460c-af5e-9a47082e1f1e
A26: =IFERROR(__xludf.DUMMYFUNCTION("""COMPUTED_VALUE"""),"2025-08-26T11:39:08.570Z") -> 2025-08-26T11:39:08.570Z | B26: =IFERROR(__xludf.DUMMYFUNCTION("""COMPUTED_VALUE"""),"2025-08-26T15:23:32.156+08") -> 2025-08-26T15:23:32.156+08 | C26: =IFERROR(__xludf.DUMMYFUNCTION("""COMPUTED_VALUE"""),"2025-08-26T15:36:22.880+08") -> 2025-08-26T15:36:22.880+08 | D26: =IFERROR(__xludf.DUMMYFUNCTION("""COMPUTED_VALUE"""),"H030821032") -> H030821032 | E26: =IFERROR(__xludf.DUMMYFUNCTION("""COMPUTED_VALUE"""),"H2846135") -> H2846135 | F26: =IFERROR(__xludf.DUMMYFUNCTION("""COMPUTED_VALUE"""),"Annalou Empanado Encontro") -> Annalou Empanado Encontro | I26: =IFERROR(__xludf.DUMMYFUNCTION("""COMPUTED_VALUE"""),"ICM_Business_linked_launch") -> ICM_Business_linked_launch | J26: =IFERROR(__xludf.DUMMYFUNCTION("""COMPUTED_VALUE"""),"uuid:5837ac91-6429-4130-9b4a-004ab2448c80") -> uuid:5837ac91-6429-4130-9b4a-004ab2448c80
A27: =IFERROR(__xludf.DUMMYFUNCTION("""COMPUTED_VALUE"""),"2025-08-26T11:41:29.956Z") -> 2025-08-26T11:41:29.956Z | B27: =IFERROR(__xludf.DUMMYFUNCTION("""COMPUTED_VALUE"""),"2025-08-26T11:20:59.633+08") -> 2025-08-26T11:20:59.633+08 | C27: =IFERROR(__xludf.DUMMYFUNCTION("""COMPUTED_VALUE"""),"2025-08-26T11:39:12.947+08") -> 2025-08-26T11:39:12.947+08 | D27: =IFERROR(__xludf.DUMMYFUNCTION("""COMPUTED_VALUE"""),"H030821027") -> H030821027 | E27: =IFERROR(__xludf.DUMMYFUNCTION("""COMPUTED_VALUE"""),"G5472901") -> G5472901 | F27: =IFERROR(__xludf.DUMMYFUNCTION("""COMPUTED_VALUE"""),"Wellyn Grace Alaban Parcia") -> Wellyn Grace Alaban Parcia | I27: =IFERROR(__xludf.DUMMYFUNCTION("""COMPUTED_VALUE"""),"ICM_Business_linked_launch") -> ICM_Business_linked_launch | J27: =IFERROR(__xludf.DUMMYFUNCTION("""COMPUTED_VALUE"""),"uuid:c4dcb4cc-dab5-424a-af3f-e9c6f516b737") -> uuid:c4dcb4cc-dab5-424a-af3f-e9c6f516b737
A28: =IFERROR(__xludf.DUMMYFUNCTION("""COMPUTED_VALUE"""),"2025-08-26T11:41:37.146Z") -> 2025-08-26T11:41:37.146Z | B28: =IFERROR(__xludf.DUMMYFUNCTION("""COMPUTED_VALUE"""),"2025-08-26T13:52:33.759+08") -> 2025-08-26T13:52:33.759+08 | C28: =IFERROR(__xludf.DUMMYFUNCTION("""COMPUTED_VALUE"""),"2025-08-26T14:08:16.507+08") -> 2025-08-26T14:08:16.507+08 | D28: =IFERROR(__xludf.DUMMYFUNCTION("""COMPUTED_VALUE"""),"H030821021") -> H030821021 | E28: =IFERROR(__xludf.DUMMYFUNCTION("""COMPUTED_VALUE"""),"G5472901") -> G5472901 | F28: =IFERROR(__xludf.DUMMYFUNCTION("""COMPUTED_VALUE"""),"Wellyn Grace Alaban Parcia") -> Wellyn Grace Alaban Parcia | I28: =IFERROR(__xludf.DUMMYFUNCTION("""COMPUTED_VALUE"""),"ICM_Business_linked_launch") -> ICM_Business_linked_launch | J28: =IFERROR(__xludf.DUMMYFUNCTION("""COMPUTED_VALUE"""),"uuid:92f9d972-bd18-48f8-9f0f-e11a9dbe2c77") -> uuid:92f9d972-bd18-48f8-9f0f-e11a9dbe2c77
A29: =IFERROR(__xludf.DUMMYFUNCTION("""COMPUTED_VALUE"""),"2025-08-26T11:41:40.275Z") -> 2025-08-26T11:41:40.275Z | B29: =IFERROR(__xludf.DUMMYFUNCTION("""COMPUTED_VALUE"""),"2025-08-26T16:36:10.397+08") -> 2025-08-26T16:36:10.397+08 | C29: =IFERROR(__xludf.DUMMYFUNCTION("""COMPUTED_VALUE"""),"2025-08-26T17:00:35.458+08") -> 2025-08-26T17:00:35.458+08 | D29: =IFERROR(__xludf.DUMMYFUNCTION("""COMPUTED_VALUE"""),"H030821018") -> H030821018 | E29: =IFERROR(__xludf.DUMMYFUNCTION("""COMPUTED_VALUE"""),"G5472901") -> G5472901 | F29: =IFERROR(__xludf.DUMMYFUNCTION("""COMPUTED_VALUE"""),"Wellyn Grace Alaban Parcia") -> Wellyn Grace Alaban Parcia | I29: =IFERROR(__xludf.DUMMYFUNCTION("""COMPUTED_VALUE"""),"ICM_Business_linked_launch") -> ICM_Business_linked_launch | J29: =IFERROR(__xludf.DUMMYFUNCTION("""COMPUTED_VALUE"""),"uuid:7b9f2ce5-a328-4056-9512-12bd9307781b") -> uuid:7b9f2ce5-a328-4056-9512-12bd9307781b
A30: =IFERROR(__xludf.DUMMYFUNCTION("""COMPUTED_VALUE"""),"2025-08-26T11:49:54.490Z") -> 2025-08-26T11:49:54.490Z | B30: =IFERROR(__xludf.DUMMYFUNCTION("""COMPUTED_VALUE"""),"2025-08-26T10:19:23.345+08") -> 2025-08-26T10:19:23.345+08 | C30: =IFERROR(__xludf.DUMMYFUNCTION("""COMPUTED_VALUE"""),"2025-08-26T10:26:10.243+08") -> 2025-08-26T10:26:10.243+08 | D30: =IFERROR(__xludf.DUMMYFUNCTION("""COMPUTED_VALUE"""),"H019575020") -> H019575020 | E30: =IFERROR(__xludf.DUMMYFUNCTION("""COMPUTED_VALUE"""),455939.0) -> 455939 | F30: =IFERROR(__xludf.DUMMYFUNCTION("""COMPUTED_VALUE"""),"Mary Jean Villaflor") -> Mary Jean Villaflor | I30: =IFERROR(__xludf.DUMMYFUNCTION("""COMPUTED_VALUE"""),"ICM_Business_linked_launch") -> ICM_Business_linked_launch | J30: =IFERROR(__xludf.DUMMYFUNCTION("""COMPUTED_VALUE"""),"uuid:9f9fd260-e89e-4361-ad71-be0779c7129e") -> uuid:9f9fd260-e89e-4361-ad71-be0779c7129e
A31: =IFERROR(__xludf.DUMMYFUNCTION("""COMPUTED_VALUE"""),"2025-08-26T11:49:58.312Z") -> 2025-08-26T11:49:58.312Z | B31: =IFERROR(__xludf.DUMMYFUNCTION("""COMPUTED_VALUE"""),"2025-08-26T11:26:13.043+08") -> 2025-08-26T11:26:13.043+08 | C31: =IFERROR(__xludf.DUMMYFUNCTION("""COMPUTED_VALUE"""),"2025-08-26T11:29:09.895+08") -> 2025-08-26T11:29:09.895+08 | D31: =IFERROR(__xludf.DUMMYFUNCTION("""COMPUTED_VALUE"""),"H019575026") -> H019575026 | E31: =IFERROR(__xludf.DUMMYFUNCTION("""COMPUTED_VALUE"""),455939.0) -> 455939 | F31: =IFERROR(__xludf.DUMMYFUNCTION("""COMPUTED_VALUE"""),"Mary Jean Villaflor") -> Mary Jean Villaflor | I31: =IFERROR(__xludf.DUMMYFUNCTION("""COMPUTED_VALUE"""),"ICM_Business_linked_launch") -> ICM_Business_linked_launch | J31: =IFERROR(__xludf.DUMMYFUNCTION("""COMPUTED_VALUE"""),"uuid:47abae0a-440c-4022-9c2c-926676b6183a") -> uuid:47abae0a-440c-4022-9c2c-926676b6183a
A32: =IFERROR(__xludf.DUMMYFUNCTION("""COMPUTED_VALUE"""),"2025-08-26T11:50:00.138Z") -> 2025-08-26T11:50:00.138Z | B32: =IFERROR(__xludf.DUMMYFUNCTION("""COMPUTED_VALUE"""),"2025-08-26T12:45:48.774+08") -> 2025-08-26T12:45:48.774+08 | C32: =IFERROR(__xludf.DUMMYFUNCTION("""COMPUTED_VALUE"""),"2025-08-26T12:47:38.108+08") -> 2025-08-26T12:47:38.108+08 | D32: =IFERROR(__xludf.DUMMYFUNCTION("""COMPUTED_VALUE"""),"H019575034") -> H019575034 | E32: =IFERROR(__xludf.DUMMYFUNCTION("""COMPUTED_VALUE"""),455939.0) -> 455939 | F32: =IFERROR(__xludf.DUMMYFUNCTION("""COMPUTED_VALUE"""),"Mary Jean Villaflor") -> Mary Jean Villaflor | I32: =IFERROR(__xludf.DUMMYFUNCTION("""COMPUTED_VALUE"""),"ICM_Business_linked_launch") -> ICM_Business_linked_launch | J32: =IFERROR(__xludf.DUMMYFUNCTION("""COMPUTED_VALUE"""),"uuid:a4e09192-dd3c-4161-ac65-49e9e2127f7f") -> uuid:a4e09192-dd3c-4161-ac65-49e9e2127f7f
A33: =IFERROR(__xludf.DUMMYFUNCTION("""COMPUTED_VALUE"""),"2025-08-26T11:50:01.252Z") -> 2025-08-26T11:50:01.252Z | B33: =IFERROR(__xludf.DUMMYFUNCTION("""COMPUTED_VALUE"""),"2025-08-26T13:31:17.426+08") -> 2025-08-26T13:31:17.426+08 | C33: =IFERROR(__xludf.DUMMYFUNCTION("""COMPUTED_VALUE"""),"2025-08-26T13:33:48.061+08") -> 2025-08-26T13:33:48.061+08 | D33: =IFERROR(__xludf.DUMMYFUNCTION("""COMPUTED_VALUE"""),"H019575029") -> H019575029 | E33: =IFERROR(__xludf.DUMMYFUNCTION("""COMPUTED_VALUE"""),455939.0) -> 455939 | F33: =IFERROR(__xludf.DUMMYFUNCTION("""COMPUTED_VALUE"""),"Mary Jean Villaflor") -> Mary Jean Villaflor | I33: =IFERROR(__xludf.DUMMYFUNCTION("""COMPUTED_VALUE"""),"ICM_Business_linked_launch") -> ICM_Business_linked_launch | J33: =IFERROR(__xludf.DUMMYFUNCTION("""COMPUTED_VALUE"""),"uuid:d23c8dc1-bffd-4786-965a-f00b7e1c7ab4") -> uuid:d23c8dc1-bffd-4786-965a-f00b7e1c7ab4
A34: =IFERROR(__xludf.DUMMYFUNCTION("""COMPUTED_VALUE"""),"2025-08-26T12:02:09.451Z") -> 2025-08-26T12:02:09.451Z | B34: =IFERROR(__xludf.DUMMYFUNCTION("""COMPUTED_VALUE"""),"2025-08-26T09:32:27.694+08") -> 2025-08-26T09:32:27.694+08 | C34: =IFERROR(__xludf.DUMMYFUNCTION("""COMPUTED_VALUE"""),"2025-08-26T10:09:40.043+08") -> 2025-08-26T10:09:40.043+08 | D34: =IFERROR(__xludf.DUMMYFUNCTION("""COMPUTED_VALUE"""),"H030255021") -> H030255021 | E34: =IFERROR(__xludf.DUMMYFUNCTION("""COMPUTED_VALUE"""),"O3925718") -> O3925718 | F34: =IFERROR(__xludf.DUMMYFUNCTION("""COMPUTED_VALUE"""),"Adrian Montecastro Ferrer") -> Adrian Montecastro Ferrer | I34: =IFERROR(__xludf.DUMMYFUNCTION("""COMPUTED_VALUE"""),"ICM_Business_linked_launch") -> ICM_Business_linked_launch | J34: =IFERROR(__xludf.DUMMYFUNCTION("""COMPUTED_VALUE"""),"uuid:18225db4-4995-4d2e-b8b7-cad4180a1d31") -> uuid:18225db4-4995-4d2e-b8b7-cad4180a1d31
A35: =IFERROR(__xludf.DUMMYFUNCTION("""COMPUTED_VALUE"""),"2025-08-26T12:02:09.825Z") -> 2025-08-26T12:02:09.825Z | B35: =IFERROR(__xludf.DUMMYFUNCTION("""COMPUTED_VALUE"""),"2025-08-26T11:48:17.985+08") -> 2025-08-26T11:48:17.985+08 | C35: =IFERROR(__xludf.DUMMYFUNCTION("""COMPUTED_VALUE"""),"2025-08-26T12:01:20.586+08") -> 2025-08-26T12:01:20.586+08 | D35: =IFERROR(__xludf.DUMMYFUNCTION("""COMPUTED_VALUE"""),"H030255020") -> H030255020 | E35: =IFERROR(__xludf.DUMMYFUNCTION("""COMPUTED_VALUE"""),"O3925718") -> O3925718 | F35: =IFERROR(__xludf.DUMMYFUNCTION("""COMPUTED_VALUE"""),"Adrian Montecastro Ferrer") -> Adrian Montecastro Ferrer | I35: =IFERROR(__xludf.DUMMYFUNCTION("""COMPUTED_VALUE"""),"ICM_Business_linked_launch") -> ICM_Business_linked_launch | J35: =IFERROR(__xludf.DUMMYFUNCTION("""COMPUTED_VALUE"""),"uuid:b24de469-d1f0-4079-8dd6-86801dec2bc6") -> uuid:b24de469-d1f0-4079-8dd6-86801dec2bc6
A36: =IFERROR(__xludf.DUMMYFUNCTION("""COMPUTED_VALUE"""),"2025-08-26T12:02:12.452Z") -> 2025-08-26T12:02:12.452Z | B36: =IFERROR(__xludf.DUMMYFUNCTION("""COMPUTED_VALUE"""),"2025-08-26T13:42:04.730+08") -> 2025-08-26T13:42:04.730+08 | C36: =IFERROR(__xludf.DUMMYFUNCTION("""COMPUTED_VALUE"""),"2025-08-26T13:51:31.185+08") -> 2025-08-26T13:51:31.185+08 | D36: =IFERROR(__xludf.DUMMYFUNCTION("""COMPUTED_VALUE"""),"H030255024") -> H030255024 | E36: =IFERROR(__xludf.DUMMYFUNCTION("""COMPUTED_VALUE"""),"O3925718") -> O3925718 | F36: =IFERROR(__xludf.DUMMYFUNCTION("""COMPUTED_VALUE"""),"Adrian Montecastro Ferrer") -> Adrian Montecastro Ferrer | I36: =IFERROR(__xludf.DUMMYFUNCTION("""COMPUTED_VALUE"""),"ICM_Business_linked_launch") -> ICM_Business_linked_launch | J36: =IFERROR(__xludf.DUMMYFUNCTION("""COMPUTED_VALUE"""),"uuid:152be913-9052-476f-a86a-e7ba27155512") -> uuid:152be913-9052-476f-a86a-e7ba27155512
A37: =IFERROR(__xludf.DUMMYFUNCTION("""COMPUTED_VALUE"""),"2025-08-26T12:09:12.644Z") -> 2025-08-26T12:09:12.644Z | B37: =IFERROR(__xludf.DUMMYFUNCTION("""COMPUTED_VALUE"""),"2025-08-26T10:10:04.674+08") -> 2025-08-26T10:10:04.674+08 | C37: =IFERROR(__xludf.DUMMYFUNCTION("""COMPUTED_VALUE"""),"2025-08-26T10:23:24.055+08") -> 2025-08-26T10:23:24.055+08 | D37: =IFERROR(__xludf.DUMMYFUNCTION("""COMPUTED_VALUE"""),"H030375034") -> H030375034 | E37: =IFERROR(__xludf.DUMMYFUNCTION("""COMPUTED_VALUE"""),"J4315980") -> J4315980 | F37: =IFERROR(__xludf.DUMMYFUNCTION("""COMPUTED_VALUE"""),"Trixie Marie Jardeleza Saber") -> Trixie Marie Jardeleza Saber | I37: =IFERROR(__xludf.DUMMYFUNCTION("""COMPUTED_VALUE"""),"ICM_Business_linked_launch") -> ICM_Business_linked_launch | J37: =IFERROR(__xludf.DUMMYFUNCTION("""COMPUTED_VALUE"""),"uuid:1bddb882-b6ae-4754-815a-ce68e40e1951") -> uuid:1bddb882-b6ae-4754-815a-ce68e40e1951
A38: =IFERROR(__xludf.DUMMYFUNCTION("""COMPUTED_VALUE"""),"2025-08-26T12:09:13.568Z") -> 2025-08-26T12:09:13.568Z | B38: =IFERROR(__xludf.DUMMYFUNCTION("""COMPUTED_VALUE"""),"2025-08-26T14:10:06.478+08") -> 2025-08-26T14:10:06.478+08 | C38: =IFERROR(__xludf.DUMMYFUNCTION("""COMPUTED_VALUE"""),"2025-08-26T14:15:34.522+08") -> 2025-08-26T14:15:34.522+08 | D38: =IFERROR(__xludf.DUMMYFUNCTION("""COMPUTED_VALUE"""),"H030375021") -> H030375021 | E38: =IFERROR(__xludf.DUMMYFUNCTION("""COMPUTED_VALUE"""),"J4315980") -> J4315980 | F38: =IFERROR(__xludf.DUMMYFUNCTION("""COMPUTED_VALUE"""),"Trixie Marie Jardeleza Saber") -> Trixie Marie Jardeleza Saber | I38: =IFERROR(__xludf.DUMMYFUNCTION("""COMPUTED_VALUE"""),"ICM_Business_linked_launch") -> ICM_Business_linked_launch | J38: =IFERROR(__xludf.DUMMYFUNCTION("""COMPUTED_VALUE"""),"uuid:0146e22c-f1eb-4cc0-b9bc-4b69cec3fb7e") -> uuid:0146e22c-f1eb-4cc0-b9bc-4b69cec3fb7e
A39: =IFERROR(__xludf.DUMMYFUNCTION("""COMPUTED_VALUE"""),"2025-08-26T12:09:14.299Z") -> 2025-08-26T12:09:14.299Z | B39: =IFERROR(__xludf.DUMMYFUNCTION("""COMPUTED_VALUE"""),"2025-08-26T12:12:15.220+08") -> 2025-08-26T12:12:15.220+08 | C39: =IFERROR(__xludf.DUMMYFUNCTION("""COMPUTED_VALUE"""),"2025-08-26T12:17:18.156+08") -> 2025-08-26T12:17:18.156+08 | D39: =IFERROR(__xludf.DUMMYFUNCTION("""COMPUTED_VALUE"""),"H030375022") -> H030375022 | E39: =IFERROR(__xludf.DUMMYFUNCTION("""COMPUTED_VALUE"""),"J4315980") -> J4315980 | F39: =IFERROR(__xludf.DUMMYFUNCTION("""COMPUTED_VALUE"""),"Trixie Marie Jardeleza Saber") -> Trixie Marie Jardeleza Saber | I39: =IFERROR(__xludf.DUMMYFUNCTION("""COMPUTED_VALUE"""),"ICM_Business_linked_launch") -> ICM_Business_linked_launch | J39: =IFERROR(__xludf.DUMMYFUNCTION("""COMPUTED_VALUE"""),"uuid:4baa8b33-e4af-4ad9-a4a4-acd24f53ea94") -> uuid:4baa8b33-e4af-4ad9-a4a4-acd24f53ea94
A40: =IFERROR(__xludf.DUMMYFUNCTION("""COMPUTED_VALUE"""),"2025-10-02T08:53:11.477Z") -> 2025-10-02T08:53:11.477Z | B40: =IFERROR(__xludf.DUMMYFUNCTION("""COMPUTED_VALUE"""),"2025-10-02T09:05:57.819+08") -> 2025-10-02T09:05:57.819+08 | C40: =IFERROR(__xludf.DUMMYFUNCTION("""COMPUTED_VALUE"""),"2025-10-02T09:19:46.386+08") -> 2025-10-02T09:19:46.386+08 | D40: =IFERROR(__xludf.DUMMYFUNCTION("""COMPUTED_VALUE"""),"H030375027") -> H030375027 | E40: =IFERROR(__xludf.DUMMYFUNCTION("""COMPUTED_VALUE"""),"J4315980") -> J4315980 | F40: =IFERROR(__xludf.DUMMYFUNCTION("""COMPUTED_VALUE"""),"Trixie Marie Jardeleza Saber") -> Trixie Marie Jardeleza Saber | I40: =IFERROR(__xludf.DUMMYFUNCTION("""COMPUTED_VALUE"""),"ICM_Business_linked_launch") -> ICM_Business_linked_launch | J40: =IFERROR(__xludf.DUMMYFUNCTION("""COMPUTED_VALUE"""),"uuid:65a45523-8ec3-4b39-82c9-1066e5ae1c6f") -> uuid:65a45523-8ec3-4b39-82c9-1066e5ae1c6f
...

Sheet Caseslist
A1: brgy_prefix | B1: Household_ID | C1: Household Survey | D1: ID | E1: FO | F1: ICM Survey | G1: ICM Survey | H1: FO | I1: FO | J1: HH Date Completed | K1: ICM Date Completed | L1: Date Completed | M1: Date Completed | N1: Treatment | O1: Treat
A2: =left(B2,7) -> H030069 | B2: H030069008 | C2: {=IF( AND( IFERROR(MATCH(Caseslist!B2, data!D:D, 0), 0) > 0, IFERROR(INDEX(data!N:N, MATCH(Caseslist!B2, data!D:D, 0)) = 1, FALSE) ), "COMPLETE", "INC" )} -> COMPLETE | D2: {=IFERROR(INDEX(data!$G:$G,match(Caseslist!B2,data!$D:$D,0)), "INC")} -> O3925718 | E2: {=IFERROR(INDEX(data!H:H,match(Caseslist!B2,data!D:D,0)), "INC")} -> Adrian Montecastro Ferrer | F2: {=IF( OR( IFNA(INDEX(data!M:M, MATCH(Caseslist!B2, data!D:D, 0)), "") = "", IFNA(INDEX(data!M:M, MATCH(Caseslist!B2, data!D:D, 0)), 0) = 0 ), "COMPLETE", IF( IFNA(INDEX(dataICM!D:D, MATCH(Caseslist!B2, dataICM!D:D, 0)), "INC") = "INC", IFNA(INDEX(dataICM!D:D, MATCH(Caseslist!B2, dataICM!D:D, 0)), "INC"), "COMPLETE" ) )} -> COMPLETE | G2: {=IF(IFERROR(INDEX(data!L:L,match(Caseslist!B2,data!D:D,0)),"INC")="","COMPLETE",F2)} -> COMPLETE | H2: {=IFERROR(INDEX(dataICM!F:F,match(Caseslist!B2,dataICM!D:D,0)), "INC")} -> INC | I2: =IF(G2="COMPLETE",D2,"INC") -> O3925718 | J2: {=IF( AND( IFERROR(MATCH(B2, data!D:D, 0), 0) > 0, IFERROR(INDEX(data!N:N, MATCH(B2, data!D:D, 0)) = 1, FALSE) ), INDEX(data!C:C, MATCH(B2, data!D:D, 0)), "INC" )} -> 2025-08-25T12:24:30.899+08 | K2: {=IFERROR(INDEX(dataICM!C:C,match(Caseslist!B2,dataICM!D:D,0)), "INC")} -> INC | L2: {=IF(AND(G2="COMPLETE", OR(K2="INC", ISBLANK(INDEX(data!O:O, ROW())))), J2, K2)} -> 2025-08-25T12:24:30.899+08 | M2: {=IFERROR(DATEVALUE(MID(L2:L2724,1,10)),"INC")} -> 45894 | N2: {=IF(M2<>"INC", INDEX(data!M:M, MATCH(B2, data!D:D, 0)), "")} | O2: =IF(AND(N2="",M2<>"INC"),0,N2) -> 0
A3: =left(B3,7) -> H030069 | B3: H030069016 | C3: {=IF( AND( IFERROR(MATCH(Caseslist!B3, data!D:D, 0), 0) > 0, IFERROR(INDEX(data!N:N, MATCH(Caseslist!B3, data!D:D, 0)) = 1, FALSE) ), "COMPLETE", "INC" )} -> COMPLETE | D3: {=IFERROR(INDEX(data!$G:$G,match(Caseslist!B3,data!$D:$D,0)), "INC")} -> M6491032 | E3: {=IFERROR(INDEX(data!H:H,match(Caseslist!B3,data!D:D,0)), "INC")} -> Rosevil Tayo Desamparado | F3: {=IF( OR( IFNA(INDEX(data!M:M, MATCH(Caseslist!B3, data!D:D, 0)), "") = "", IFNA(INDEX(data!M:M, MATCH(Caseslist!B3, data!D:D, 0)), 0) = 0 ), "COMPLETE", IF( IFNA(INDEX(dataICM!D:D, MATCH(Caseslist!B3, dataICM!D:D, 0)), "INC") = "INC", IFNA(INDEX(dataICM!D:D, MATCH(Caseslist!B3, dataICM!D:D, 0)), "INC"), "COMPLETE" ) )} -> COMPLETE | G3: {=IF(IFERROR(INDEX(data!L:L,match(Caseslist!B3,data!D:D,0)),"INC")="","COMPLETE",F3)} -> COMPLETE | H3: {=IFERROR(INDEX(dataICM!F:F,match(Caseslist!B3,dataICM!D:D,0)), "INC")} -> INC | I3: =IF(G3="COMPLETE",D3,"INC") -> M6491032 | J3: {=IF( AND( IFERROR(MATCH(B3, data!D:D, 0), 0) > 0, IFERROR(INDEX(data!N:N, MATCH(B3, data!D:D, 0)) = 1, FALSE) ), INDEX(data!C:C, MATCH(B3, data!D:D, 0)), "INC" )} -> 2025-08-25T11:53:45.055+08 | K3: {=IFERROR(INDEX(dataICM!C:C,match(Caseslist!B3,dataICM!D:D,0)), "INC")} -> INC | L3: {=IF(AND(G3="COMPLETE", OR(K3="INC", ISBLANK(INDEX(data!O:O, ROW())))), J3, K3)} -> 2025-08-25T11:53:45.055+08 | M3: 45894 | N3: {=IF(M3<>"INC", INDEX(data!M:M, MATCH(B3, data!D:D, 0)), "")} | O3: =IF(AND(N3="",M3<>"INC"),0,N3) -> 0
A4: =left(B4,7) -> H030069 | B4: H030069017 | C4: {=IF( AND( IFERROR(MATCH(Caseslist!B4, data!D:D, 0), 0) > 0, IFERROR(INDEX(data!N:N, MATCH(Caseslist!B4, data!D:D, 0)) = 1, FALSE) ), "COMPLETE", "INC" )} -> COMPLETE | D4: {=IFERROR(INDEX(data!$G:$G,match(Caseslist!B4,data!$D:$D,0)), "INC")} -> N7814260 | E4: {=IFERROR(INDEX(data!H:H,match(Caseslist!B4,data!D:D,0)), "INC")} -> Jemma Marie Tillo | F4: {=IF( OR( IFNA(INDEX(data!M:M, MATCH(Caseslist!B4, data!D:D, 0)), "") = "", IFNA(INDEX(data!M:M, MATCH(Caseslist!B4, data!D:D, 0)), 0) = 0 ), "COMPLETE", IF( IFNA(INDEX(dataICM!D:D, MATCH(Caseslist!B4, dataICM!D:D, 0)), "INC") = "INC", IFNA(INDEX(dataICM!D:D, MATCH(Caseslist!B4, dataICM!D:D, 0)), "INC"), "COMPLETE" ) )} -> COMPLETE | G4: {=IF(IFERROR(INDEX(data!L:L,match(Caseslist!B4,data!D:D,0)),"INC")="","COMPLETE",F4)} -> COMPLETE | H4: {=IFERROR(INDEX(dataICM!F:F,match(Caseslist!B4,dataICM!D:D,0)), "INC")} -> INC | I4: =IF(G4="COMPLETE",D4,"INC") -> N7814260 | J4: {=IF( AND( IFERROR(MATCH(B4, data!D:D, 0), 0) > 0, IFERROR(INDEX(data!N:N, MATCH(B4, data!D:D, 0)) = 1, FALSE) ), INDEX(data!C:C, MATCH(B4, data!D:D, 0)), "INC" )} -> 2025-08-25T14:52:27.078+08 | K4: {=IFERROR(INDEX(dataICM!C:C,match(Caseslist!B4,dataICM!D:D,0)), "INC")} -> INC | L4: {=IF(AND(G4="COMPLETE", OR(K4="INC", ISBLANK(INDEX(data!O:O, ROW())))), J4, K4)} -> 2025-08-25T14:52:27.078+08 | M4: 45894 | N4: {=IF(M4<>"INC", INDEX(data!M:M, MATCH(B4, data!D:D, 0)), "")} | O4: =IF(AND(N4="",M4<>"INC"),0,N4) -> 0
A5: =left(B5,7) -> H030069 | B5: H030069018 | C5: {=IF( AND( IFERROR(MATCH(Caseslist!B5, data!D:D, 0), 0) > 0, IFERROR(INDEX(data!N:N, MATCH(Caseslist!B5, data!D:D, 0)) = 1, FALSE) ), "COMPLETE", "INC" )} -> COMPLETE | D5: {=IFERROR(INDEX(data!$G:$G,match(Caseslist!B5,data!$D:$D,0)), "INC")} -> O3925718 | E5: {=IFERROR(INDEX(data!H:H,match(Caseslist!B5,data!D:D,0)), "INC")} -> Adrian Montecastro Ferrer | F5: {=IF( OR( IFNA(INDEX(data!M:M, MATCH(Caseslist!B5, data!D:D, 0)), "") = "", IFNA(INDEX(data!M:M, MATCH(Caseslist!B5, data!D:D, 0)), 0) = 0 ), "COMPLETE", IF( IFNA(INDEX(dataICM!D:D, MATCH(Caseslist!B5, dataICM!D:D, 0)), "INC") = "INC", IFNA(INDEX(dataICM!D:D, MATCH(Caseslist!B5, dataICM!D:D, 0)), "INC"), "COMPLETE" ) )} -> COMPLETE | G5: {=IF(IFERROR(INDEX(data!L:L,match(Caseslist!B5,data!D:D,0)),"INC")="","COMPLETE",F5)} -> COMPLETE | H5: {=IFERROR(INDEX(dataICM!F:F,match(Caseslist!B5,dataICM!D:D,0)), "INC")} -> INC | I5: =IF(G5="COMPLETE",D5,"INC") -> O3925718 | J5: {=IF( AND( IFERROR(MATCH(B5, data!D:D, 0), 0) > 0, IFERROR(INDEX(data!N:N, MATCH(B5, data!D:D, 0)) = 1, FALSE) ), INDEX(data!C:C, MATCH(B5, data!D:D, 0)), "INC" )} -> 2025-08-25T13:34:43.797+08 | K5: {=IFERROR(INDEX(dataICM!C:C,match(Caseslist!B5,dataICM!D:D,0)), "INC")} -> INC | L5: {=IF(AND(G5="COMPLETE", OR(K5="INC", ISBLANK(INDEX(data!O:O, ROW())))), J5, K5)} -> 2025-08-25T13:34:43.797+08 | M5: 45894 | N5: {=IF(M5<>"INC", INDEX(data!M:M, MATCH(B5, data!D:D, 0)), "")} | O5: =IF(AND(N5="",M5<>"INC"),0,N5) -> 0
A6: =left(B6,7) -> H030069 | B6: H030069019 | C6: {=IF( AND( IFERROR(MATCH(Caseslist!B6, data!D:D, 0), 0) > 0, IFERROR(INDEX(data!N:N, MATCH(Caseslist!B6, data!D:D, 0)) = 1, FALSE) ), "COMPLETE", "INC" )} -> COMPLETE | D6: {=IFERROR(INDEX(data!$G:$G,match(Caseslist!B6,data!$D:$D,0)), "INC")} -> P1068432 | E6: {=IFERROR(INDEX(data!H:H,match(Caseslist!B6,data!D:D,0)), "INC")} -> Mark Daniel Balagao Benson | F6: {=IF( OR( IFNA(INDEX(data!M:M, MATCH(Caseslist!B6, data!D:D, 0)), "") = "", IFNA(INDEX(data!M:M, MATCH(Caseslist!B6, data!D:D, 0)), 0) = 0 ), "COMPLETE", IF( IFNA(INDEX(dataICM!D:D, MATCH(Caseslist!B6, dataICM!D:D, 0)), "INC") = "INC", IFNA(INDEX(dataICM!D:D, MATCH(Caseslist!B6, dataICM!D:D, 0)), "INC"), "COMPLETE" ) )} -> COMPLETE | G6: {=IF(IFERROR(INDEX(data!L:L,match(Caseslist!B6,data!D:D,0)),"INC")="","COMPLETE",F6)} -> COMPLETE | H6: {=IFERROR(INDEX(dataICM!F:F,match(Caseslist!B6,dataICM!D:D,0)), "INC")} -> INC | I6: =IF(G6="COMPLETE",D6,"INC") -> P1068432 | J6: {=IF( AND( IFERROR(MATCH(B6, data!D:D, 0), 0) > 0, IFERROR(INDEX(data!N:N, MATCH(B6, data!D:D, 0)) = 1, FALSE) ), INDEX(data!C:C, MATCH(B6, data!D:D, 0)), "INC" )} -> 2025-08-25T12:40:04.683+08 | K6: {=IFERROR(INDEX(dataICM!C:C,match(Caseslist!B6,dataICM!D:D,0)), "INC")} -> INC | L6: {=IF(AND(G6="COMPLETE", OR(K6="INC", ISBLANK(INDEX(data!O:O, ROW())))), J6, K6)} -> 2025-08-25T12:40:04.683+08 | M6: 45894 | N6: {=IF(M6<>"INC", INDEX(data!M:M, MATCH(B6, data!D:D, 0)), "")} | O6: =IF(AND(N6="",M6<>"INC"),0,N6) -> 0
A7: =left(B7,7) -> H030069 | B7: H030069021 | C7: {=IF( AND( IFERROR(MATCH(Caseslist!B7, data!D:D, 0), 0) > 0, IFERROR(INDEX(data!N:N, MATCH(Caseslist!B7, data!D:D, 0)) = 1, FALSE) ), "COMPLETE", "INC" )} -> COMPLETE | D7: {=IFERROR(INDEX(data!$G:$G,match(Caseslist!B7,data!$D:$D,0)), "INC")} -> P1068432 | E7: {=IFERROR(INDEX(data!H:H,match(Caseslist!B7,data!D:D,0)), "INC")} -> Mark Daniel Balagao Benson | F7: {=IF( OR( IFNA(INDEX(data!M:M, MATCH(Caseslist!B7, data!D:D, 0)), "") = "", IFNA(INDEX(data!M:M, MATCH(Caseslist!B7, data!D:D, 0)), 0) = 0 ), "COMPLETE", IF( IFNA(INDEX(dataICM!D:D, MATCH(Caseslist!B7, dataICM!D:D, 0)), "INC") = "INC", IFNA(INDEX(dataICM!D:D, MATCH(Caseslist!B7, dataICM!D:D, 0)), "INC"), "COMPLETE" ) )} -> COMPLETE | G7: {=IF(IFERROR(INDEX(data!L:L,match(Caseslist!B7,data!D:D,0)),"INC")="","COMPLETE",F7)} -> COMPLETE | H7: {=IFERROR(INDEX(dataICM!F:F,match(Caseslist!B7,dataICM!D:D,0)), "INC")} -> INC | I7: =IF(G7="COMPLETE",D7,"INC") -> P1068432 | J7: {=IF( AND( IFERROR(MATCH(B7, data!D:D, 0), 0) > 0, IFERROR(INDEX(data!N:N, MATCH(B7, data!D:D, 0)) = 1, FALSE) ), INDEX(data!C:C, MATCH(B7, data!D:D, 0)), "INC" )} -> 2025-08-25T14:20:53.301+08 | K7: {=IFERROR(INDEX(dataICM!C:C,match(Caseslist!B7,dataICM!D:D,0)), "INC")} -> INC | L7: {=IF(AND(G7="COMPLETE", OR(K7="INC", ISBLANK(INDEX(data!O:O, ROW())))), J7, K7)} -> 2025-08-25T14:20:53.301+08 | M7: 45894 | N7: {=IF(M7<>"INC", INDEX(data!M:M, MATCH(B7, data!D:D, 0)), "")} | O7: =IF(AND(N7="",M7<>"INC"),0,N7) -> 0
